<?xml version="1.0"?>
<!-- Iertial calculated by ML from collision.stl -->
<!--<robot name="boroscope" xmlns:xacro="http://ros.org/wiki/xacro"> -->
<robot name="boroscope" xmlns:xacro="http://wiki.ros.org/xacro">
    <xacro:macro name="boroscope" params="prefix">

  <xacro:property name="bolen" value="0.2" />
  <xacro:property name="borad" value="0.003" />


   <material name="blue">
     <color rgba="0 0 0.8 1"/>
   </material>

   <material name="white">
     <color rgba="1 1 1 1"/>
   </material>

   <material name="green">
     <color rgba="0 0.8 0 1"/>
   </material>

   <material name="red">
     <color rgba="1 0 0 1"/>
   </material>

   <material name="black">
     <color rgba="0 0 0 1"/>
   </material>


  <link name="base_link">
    <origin xyz="0.0 0.0 0.0" rpy="0.0 0.0 0.0"/>
  </link>

  <joint name="base_fixed" type="fixed">
    <parent link="base_link"/>
    <child link="test_object"/>
    <origin xyz="0 0 0" rpy="0 0 0"/>		
    <limit effort="0" velocity="0" lower="0" upper="0"/>
    <dynamics damping="0.0" friction="0.0"/>
  </joint>

  <link name="test_object">
    <inertial>
     <origin xyz="-0.0000003 -0.0000004 0.0313974" rpy="0 0 0"/>
     <mass value="1.5"/>
     <inertia ixx="0.00000451719"  ixy="0.00000000132"  ixz="0.00000000004" iyy="0.00000451874" iyz="0.00000000003" izz="0.00000856920" />
    </inertial>
    <visual>
      <geometry>
        <mesh filename="package://boroscope_support/meshes/visual/test_object.stl"/>
      </geometry>
      <origin xyz="0 0 0" rpy="0 0 0"/>
      <material name="white"/>
    </visual>
    <collision>
      <geometry>
        <mesh filename="package://boroscope_support/meshes/collision/test_object.stl"/>
      </geometry>
      <origin xyz="0 0 0" rpy=" 0 0 0"/>
    </collision>
  </link>
<!--
Center of Mass is -0.0000003 -0.0000004 0.0313974
| 0.00000451719 0.00000000132 0.00000000004 |
| 0.00000000132 0.00000451874 0.00000000003 |
| 0.00000000004 0.00000000003 0.00000856920 |
-->
  <joint name="blisk_rotate" type="continuous">
    <parent link="test_object"/>
    <child link="urs150bcc"/>
    <axis xyz="0 1 0"/>
    <origin xyz="0 0 -0.0495" rpy="-${3.14159265359/2} 0 0"/> 		
    <limit effort="20" velocity="0.1"/>
    <dynamics damping="0.7" friction="0.0"/>
  </joint>

  <link name="urs150bcc">
    <inertial>
      <mass value="3.4" />
	<origin xyz="-0.0384117 0.0187346 -0.0024136" rpy="0.0 0.0 0.0"/>
      <inertia ixx="0.00000304251" ixy="-0.00000001466" ixz="-0.00000037958" iyy="0.00001062870" iyz="-0.00000000036" izz="0.00000792402" />
    </inertial>
    <visual>
      <geometry>
        <mesh filename="package://boroscope_support/meshes/visual/urs150bcc.stl"/>
      </geometry>
      <origin xyz="0 -0.015 0" rpy="${3.14159265359} ${3.14159265359} 0"/>
      <material name="black"/>
    </visual>
    <collision>
      <geometry>
        <mesh filename="package://boroscope_support/meshes/collision/urs150bcc.stl"/>
      </geometry>
      <origin xyz="0 -0.015 0" rpy="${3.14159265359} ${3.14159265359} 0"/>
    </collision>
  </link>
<!--
Center of Mass is -0.0384117 0.0187346 -0.0024136
| 0.00000304251 -0.00000001466 -0.00000037958 |
| -0.00000001466 0.00001062870 -0.00000000036 |
| -0.00000037958 -0.00000000036 0.00000792402 |
-->
  <joint name="adapter_uts150cc_to_urs150bcc_fix" type="fixed">
    <parent link="urs150bcc"/>
    <child link="adapter_uts150cc_to_urs150bcc"/>
    <origin xyz="0 0 0" rpy="0 0 0"/> 		
    <limit effort="0" velocity="0" lower="0" upper="0"/>
    <dynamics damping="0.0" friction="0.0"/>
  </joint>

  <link name="adapter_uts150cc_to_urs150bcc">
    <inertial>
      <mass value="0.5" />
	<origin xyz="0.0 0.0 0.0034931" rpy="0.0 0.0 0.0"/>
      <inertia ixx="0.00000073444" ixy="0.0" ixz="0.0" iyy="0.00000073444" iyz="0.0" izz="0.00000145840" />
    </inertial>
    <visual>
      <geometry>
        <mesh filename="package://boroscope_support/meshes/visual/adapter_uts150cc_to_urs150bcc.stl"/>
      </geometry>
      <origin xyz="0.0 -0.005 0.0" rpy="1.57 0 0"/>
      <material name="White"/>
    </visual>
    <collision>
      <geometry>
        <mesh filename="package://boroscope_support/meshes/collision/adapter_uts150cc_to_urs150bcc.stl"/>
      </geometry>
      <origin xyz="0.0 -0.005 0.0" rpy="1.57 0 0"/>
    </collision>
  </link>
<!--
Center of Mass is 0.000000 -0.000000 0.0034931
| 0.00000073444 0.000000 -0.000000 |
| 0.000000 0.00000073444 -0.000000 |
| -0.000000 -0.000000 0.00000145840 |
-->
  <joint name="horizontal_y" type="prismatic">
    <parent link="adapter_uts150cc_to_urs150bcc"/>
    <child link="uts150cc"/>
    <axis xyz="0 1 0"/>
    <origin xyz="0.0 0.302 0.0" rpy="1.5707963267948966 0.0 0.0"/> 		
    <limit effort="10" velocity="0.1" lower="-0.05" upper="0.05"/>
    <dynamics damping="0.8" friction="0.0"/>
  </joint>

  <link name="uts150cc">
    <inertial>
      <mass value="3.2" />
	<origin xyz="0.0433911 0.0157576 0.0011992" rpy="0.0 0.0 0.0"/>
      <inertia ixx="0.00000121518" ixy="-0.00000009336" ixz="-0.00000020293" iyy="0.00001703951" iyz="-0.00000000116" izz="0.00001607592" />
    </inertial>
    <visual>
      <geometry>
        <mesh filename="package://boroscope_support/meshes/visual/uts150cc.stl"/>
      </geometry>
      <origin xyz="0 0 0.27" rpy="${3.14159265359/2} 0 ${3.14159265359/2}"/>
      <material name="blue"/>
    </visual>
    <collision>
      <geometry>
        <mesh filename="package://boroscope_support/meshes/collision/uts150cc.stl"/>
      </geometry>
      <origin xyz="0 0 0.27" rpy="${3.14159265359/2} 0 ${3.14159265359/2}"/>
    </collision>
  </link>
<!--
Center of Mass is 0.0486338 0.0170175 0.0009344
| 0.00000121518 -0.00000009336 -0.00000020293 |
| -0.00000009336 0.00001703951 -0.00000000116 |
| -0.00000020293 -0.00000000116 0.00001607592 |
-->
  <joint name="Yachse_fix" type="fixed">
    <parent link="uts150cc"/>
    <child link="adapter_table_to_uts150cc"/>
    <origin xyz="0 0 0" rpy="0 0 0"/> 		
    <limit effort="0" velocity="0" lower="0" upper="0"/>
    <dynamics damping="0.0" friction="0.0"/>
  </joint>

  <link name="adapter_table_to_uts150cc">
    <inertial>
      <mass value="2" />
	<origin xyz="-0.0000026 0.0000017 -0.1350026" rpy="0.0 0.0 0.0"/>
      <inertia ixx="0.00014771446" ixy="-0.000000000" ixz="-0.000000000" iyy="0.00012059044" iyz="0.000000000" izz="0.00010923643" />
    </inertial>
    <visual>
      <geometry>
        <mesh filename="package://boroscope_support/meshes/visual/adapter_table_to_uts150cc.stl"/>
      </geometry>
      <origin xyz="0 0 0.0" rpy=" 0 ${3.14159265359} 0"/>
      <material name="white"/>
    </visual>
    <collision>
      <geometry>
        <mesh filename="package://boroscope_support/meshes/collision/adapter_table_to_uts150cc.stl"/>
      </geometry>
      <origin xyz="0 0 0" rpy=" 0 ${3.14159265359} 0"/>
    </collision>
  </link>
<!--
Center of Mass is 0.000000 0.000000 -0.1350026
| 0.00014771446 0.000000 -0.000000 |
| 0.000000 0.00012059044 -0.000000 |
| -0.000000 -0.000000 0.00010923643 |
-->
  <joint name="optical_table_fix" type="fixed">
    <parent link="adapter_table_to_uts150cc"/>
    <child link="optical_table"/>
    <origin xyz="-0.1 -0.05 0.0" rpy="0 0 0"/> <!--xyz="-0.4 -0.225 0"/-->	
    <limit effort="0" velocity="0" lower="0" upper="0"/>
    <dynamics damping="0.0" friction="0.0"/>
  </joint>

  <link name="optical_table">
    <inertial>
      <mass value="200" />
	<origin xyz="-0.0000563 -0.0000961 0.3303062" rpy="0.0 0.0 0.0"/>
      <inertia ixx="0.06395888672" ixy="0.00000010727" ixz="0.00000400768" iyy="0.09856333008" iyz="0.00000679038" izz="0.11754208984" />
    </inertial>
    <visual>
      <geometry>
        <mesh filename="package://boroscope_support/meshes/visual/optical_table_top.stl"/>
      </geometry>
      <origin xyz="0 0 0" rpy="${3.14159265359/2} 0 ${3.14159265359}"/>
      <material name="white"/>
    </visual>
    <collision>
      <geometry>
        <mesh filename="package://boroscope_support/meshes/collision/optical_table_top.stl"/>
      </geometry>
      <origin xyz="0 0 0" rpy="${3.14159265359/2} 0 ${3.14159265359}"/>
    </collision>
  </link>
<!--
Center of Mass is -0.0000563 -0.0000961 0.3303062
| 0.06395888672 0.00000010727 0.00000400768 |
| 0.00000010727 0.09856333008 0.00000679038 |
| 0.00000400768 0.00000679038 0.11754208984 |
-->
  <joint name="ims300pp_fix" type="fixed">
    <parent link="optical_table"/>
    <child link="ims300pp"/>
    <origin xyz="-0.3 -0.225 0.0" rpy="0 0 0"/> <!--xyz="0.4 0.225 0"/-->	
    <limit effort="0" velocity="0" lower="0" upper="0"/>
    <dynamics damping="0.0" friction="0.0"/>
  </joint>


  <link name="ims300pp">
    <inertial>
      <mass value="17" />
	<origin xyz="0.0010230 0.0426795 -0.0558591" rpy="0.0 0.0 0.0"/>
      <inertia ixx="0.00036375000" ixy="-0.00000005380" ixz="0.00000105232" iyy="0.00038540276" iyz="-0.00000123537" izz="0.00003385839" />
    </inertial>
    <visual>
      <geometry>
        <mesh filename="package://boroscope_support/meshes/visual/ims300pp.stl"/>
      </geometry>
      <origin xyz="0 0 0" rpy=" ${3.14159265359/2} 0 -${3.14159265359/2}"/>
      <material name="blue"/>
    </visual>
    <collision>
      <geometry>
        <mesh filename="package://boroscope_support/meshes/collision/ims300pp.stl"/>
      </geometry>
      <origin xyz="0 0 0" rpy=" ${3.14159265359/2} 0 -${3.14159265359/2}"/>
    </collision>
  </link>
<!--
Center of Mass is 0.0010230 0.0426795 -0.0558591
| 0.00036375000 -0.00000005380 0.00000105232 |
| -0.00000005380 0.00038540276 -0.00000123537 |
| 0.00000105232 -0.00000123537 0.00003385839 |
-->

  <link name="eq180">
    <inertial>
      <mass value="10" />
	<origin xyz="0.0272547 0.2619619 0.0000001" rpy="0.0 0.0 0.0"/>
      <inertia ixx="0.00049096935" ixy="-0.00002300566" ixz="0.00000000001" iyy="0.00006598664" iyz="0.00000000009" izz="0.00048218391" />
    </inertial>

    <visual>
      <geometry>
        <mesh filename="package://boroscope_support/meshes/visual/eq180.stl"/>
      </geometry>
      <origin xyz="-0.03 0 0" rpy=" 0 0 0"/>
      <material name="white"/>
    </visual>
    <collision>
      <geometry>
        <mesh filename="package://boroscope_support/meshes/collision/eq180.stl"/>
      </geometry>
      <origin xyz="-0.03 0 0" rpy=" 0 0 0"/>
    </collision>
  </link>
<!--
Center of Mass is 0.0272547 0.2619619 0.0000001
| 0.00049096935 -0.00002300566 0.00000000001 |
| -0.00002300566 0.00006598664 0.00000000009 |
| 0.00000000001 0.00000000009 0.00048218391 |
-->
  <joint name="horizontal_x" type="prismatic">
    <parent link="ims300pp"/>
    <child link="eq180"/>
    <axis xyz="0 0 1"/>
    <origin xyz="0.009 0 0.077" rpy=" ${3.14159265359/2} 0 ${3.14159265359/2}"/>
    <limit effort="10" velocity="0.1" lower="-0.15" upper="0.15"/>
    <dynamics damping="0.7" friction="0.0"/>		
  </joint>

  <link name="ims300v">
    <inertial>
      <mass value="17" />
	<origin xyz="-0.0009126 0.0369926 -0.2031119" rpy="0.0 0.0 0.0"/>
      <inertia ixx="0.00038835354" ixy="0.00000001395" ixz="0.00000090129" iyy="0.00040955441" iyz="0.00000002844" izz="0.00002962052" />
    </inertial>
    <visual>
      <geometry>
        <mesh filename="package://boroscope_support/meshes/visual/ims300v.stl"/>
      </geometry>
      <origin xyz="0.045 0.62 0" rpy="-${3.14159265359/2} -${3.14159265359/2} 0"/>
      <material name="white"/>  
    </visual>
    <collision>
      <geometry>
        <mesh filename="package://boroscope_support/meshes/collision/ims300v.stl"/>
      </geometry>
      <origin xyz="0.045 0.62 0" rpy="-${3.14159265359/2} -${3.14159265359/2} 0"/>
    </collision>
  </link>
<!--
Center of Mass is -0.0009126 0.0369926 -0.2031119
| 0.00038835354 0.00000001395 0.00000090129 |
| 0.00000001395 0.00040955441 0.00000002844 |
| 0.000000090129 0.00000002844 0.00002962052 |
-->
  <joint name="fixed_vertical" type="fixed">
    <parent link="eq180"/>
    <child link="ims300v"/>
    <origin xyz="0 0 0" rpy="0 0 0"/> 		
    <limit effort="0" velocity="0" lower="0" upper="0"/>
    <dynamics damping="0.0" friction="0.0"/>
  </joint>

  <link name="adapter_ims300v_to_bgs80cc">
   <inertial>
      <mass value="0.9" />
	<origin xyz="0.0395805 0.0436535 -0.0000010" rpy="0.0 0.0 0.0"/>
      <inertia ixx="0.00002216315" ixy="-0.00000304547" ixz="-0.00000000018" iyy="0.00001449834" iyz="-0.00000000014" izz="0.00002016665" />
    </inertial>
    <visual>
      <geometry>
        <mesh filename="package://boroscope_support/meshes/visual/adapter_ims300v_to_bgs80cc.stl"/>
      </geometry>
      <origin xyz="0 0 0" rpy="-${3.14159265359/2} 0 0"/>
      <material name="green"/>
    </visual>
   <collision>
      <geometry>
        <mesh filename="package://boroscope_support/meshes/collision/adapter_ims300v_to_bgs80cc.stl"/>
      </geometry>
      <!--<origin xyz="0 -0.0895 -0.16" rpy="${3.14159265359/2} 0 ${3.14159265359/2}"/>-->
      <origin xyz="0 0 0" rpy="-${3.14159265359/2} 0 0"/>
    </collision>
  </link>
<!--
Center of Mass is 0.0395805 0.0436535 -0.0000010
| 0.00002216315 -0.00000304547 -0.00000000018 |
| -0.00000304547 0.00001449834 -0.00000000014 |
| -0.00000000018 -0.00000000014 0.00002016665 |
-->
  <joint name="vertical_z" type="prismatic">
    <parent link="ims300v"/>
    <child link="adapter_ims300v_to_bgs80cc"/>
    <axis xyz="0 0 1"/>
    <origin xyz="0.1228 0.3615 0" rpy=" -${3.14159265359/2} 0 0"/>
    <limit effort="10" velocity="0.1" lower="-0.15" upper="0.15"/>
    <dynamics damping="0.8" friction="0.0"/>
  </joint>
  

  <link name="bgs80cc">
   <inertial>
      <mass value="2.1" />
	<origin xyz="0.0477711 -0.0730440 0.0000488" rpy="0.0 0.0 0.0"/>
      <inertia ixx="0.00000098079" ixy="0.00000009504" ixz="-0.00000000123" iyy="0.00000542688" iyz="0.00000000086" izz="0.00000497406" />
    </inertial>
    <visual>
      <geometry>
        <mesh filename="package://boroscope_support/meshes/visual/bgs80cc.stl"/>
      </geometry>
      <origin xyz="0.1007 0 0.01" rpy="${3.14159265359/2} 0 0"/>
      <material name="blue"/>
    </visual>
   <collision>
      <geometry>
        <mesh filename="package://boroscope_support/meshes/collision/bgs80cc.stl"/>
      </geometry>
      <origin xyz="0.1007 0 0.01" rpy="${3.14159265359/2} 0 0"/>
    </collision>
  </link>
<!--
Center of Mass is 0.0477711 -0.0730440 0.0000488
| 0.00000098079 0.00000009504 -0.00000000123 |
| 0.00000009504 0.00000542688 0.00000000086 |
| -0.00000000123 0.00000000086 0.00000497406 |
-->
  <joint name="fix_go" type="fixed">
    <parent link="adapter_ims300v_to_bgs80cc"/>
    <child link="bgs80cc"/>
    <origin xyz="0 0 0" rpy="0 0 0"/> 		
    <limit effort="0" velocity="0" lower="0" upper="0"/>
    <dynamics damping="0.0" friction="0.0"/>
  </joint>


  <link name="measuring_system">
   <inertial>
      <mass value="1.5" />
	<origin xyz="0.0180561 -0.0098927 -0.0546269" rpy="0.0 0.0 0.0"/>
      <inertia ixx="0.00000147864" ixy="-0.00000007280" ixz="0.00000028363" iyy="0.00000166953" iyz="0.00000021929" izz="0.00000065700" />
    </inertial>
    <visual>
      <geometry>
        <mesh filename="package://boroscope_support/meshes/visual/measuring_system.stl"/>
      </geometry>
      <origin xyz="0 0 0" rpy=" 0 0 0"/>
      <material name="blue"/>
    </visual>
   <collision>
      <geometry>
        <mesh filename="package://boroscope_support/meshes/collision/measuring_system.stl"/>
      </geometry>
      <origin xyz="0 0 0" rpy=" 0 0 0"/>
    </collision>
  </link>
<!--
Center of Mass is 0.0180561 -0.0098927 -0.0546269
| 0.00000147864 -0.00000007280 0.00000028363 |
| -0.00000007280 0.00000166953 0.00000021929 |
| 0.000000028363 0.00000021929 0.00000065700 |
-->
  <joint name="boro_theta" type="revolute">
    <parent link="bgs80cc"/>
    <child link="measuring_system"/>
    <axis xyz="0 0 1"/>
    <origin xyz="0.1007 0 0.01" rpy="${3.14159265359/2} 0 0"/>
    <limit effort="20" velocity="0.1" lower="-0.6" upper="0.6"/>
    <dynamics damping="0.7" friction="0.0"/>
  </joint>




    </xacro:macro>
</robot>
